Workbook

Sheet Legenda
A1: 1) Brasil e UFs - Participação do volume de serviços das 27 unidades da federação no total do Brasil, a partir da média dos índices de base fixa de 2022 (ano-base).
A2: 2) UF_AD - Participação do volume de serviços das 5 principais atividades de divulgação, nas 12 UFs em que há publicação de abertura setorial no nível regional, a partir da média dos índices de base fixa de 2022 (ano-base).
A3: 3 ) ADs_ Setores e Subsetores - Participação do volume de serviços das 5 principais atividades de divulgação (e suas desagragações) no total do Brasil, a partir da média dos índices de base fixa de 2022 (ano-base).
A4: 4) Segmentos - Participação do volume de serviços nos 19 segmentos de serviços mais desagregados no total do Brasil, a partir da média dos índices de base fixa de 2022 (ano-base).
A5: 5) Turismo_UFs - Participação do volume das atividades turísticas, em cada uma das 12 UFs em que há publicação deste agregado especial, no total do Brasil, a partir da média dos índices de base fixa de 2022 (ano-base).

Sheet Brasil e UFs
A1: Unidade da Federação | B1: Part.Vol (Base 2022)
A2: Rondônia | B2: 0.0020443303
A3: Acre | B3: 0.00079246518
A4: Amazonas | B4: 0.011383499
A5: Roraima | B5: 0.00077520227
A6: Pará | B6: 0.010865676
A7: Amapá | B7: 0.00071760754
A8: Tocantins | B8: 0.0020016704
A9: Maranhão | B9: 0.0068577069
A10: Piauí | B10: 0.0028251263
A11: Ceará | B11: 0.0171776
A12: Rio Grande do Norte | B12: 0.0047526007
A13: Paraíba | B13: 0.0040973705
... A28: Distrito Federal | B28: 0.024664906
A29: BRASIL | B29: =SUM(B2:B28) -> 1

Sheet UF_AD
A1: Unidade da Federação / Atividade de Divulgação | B1: Pesos_vol (Base 2022)
A2: CEARÁ | B2: =SUM(B3:B7) -> 1
A3: Serviços prestados às famílias | B3: 0.10469185
A4: Serviços de informação e comunicação | B4: 0.20072553
A5: Serviços profissionais, administrativos e complementares | B5: 0.32026568
A6: Transportes, serviços auxiliares dos transportes e correio | B6: 0.30076526
A7: Outros serviços | B7: 0.07355168
A8: PERNAMBUCO | B8: =SUM(B9:B13) -> 1
A9: Serviços prestados às famílias | B9: 0.11998274
A10: Serviços de informação e comunicação | B10: 0.17857085
A11: Serviços profissionais, administrativos e complementares | B11: 0.24263466
A12: Transportes, serviços auxiliares dos transportes e correio | B12: 0.38801926
A13: Outros serviços | B13: 0.070792493
A14: BAHIA | B14: =SUM(B15:B19) -> 1
A15: Serviços prestados às famílias | B15: 0.1259368
A16: Serviços de informação e comunicação | B16: 0.14230936
A17: Serviços profissionais, administrativos e complementares | B17: 0.22583841
A18: Transportes, serviços auxiliares dos transportes e correio | B18: 0.46404385
A19: Outros serviços | B19: 0.041871579
A20: MINAS GERAIS | B20: =SUM(B21:B25) -> 1
A21: Serviços prestados às famílias | B21: 0.067334487
A22: Serviços de informação e comunicação | B22: 0.2299576
A23: Serviços profissionais, administrativos e complementares | B23: 0.23657964
A24: Transportes, serviços auxiliares dos transportes e correio | B24: 0.39668594
A25: Outros serviços | B25: 0.069442331
A26: ESPÍRITO SANTO | B26: =SUM(B27:B31) -> 1
A27: Serviços prestados às famílias | B27: 0.087392751
A28: Serviços de informação e comunicação | B28: 0.1477431
A29: Serviços profissionais, administrativos e complementares | B29: 0.15636876
A30: Transportes, serviços auxiliares dos transportes e correio | B30: 0.54234661
A31: Outros serviços | B31: 0.066148784
A32: RIO DE JANEIRO | B32: =SUM(B33:B37) -> 1
A33: Serviços prestados às famílias | B33: 0.10610713
A34: Serviços de informação e comunicação | B34: 0.25626646
A35: Serviços profissionais, administrativos e complementares | B35: 0.18772178
A36: Transportes, serviços auxiliares dos transportes e correio | B36: 0.37822978
A37: Outros serviços | B37: 0.071674853
A38: SÃO PAULO | B38: =SUM(B39:B43) -> 1
A39: Serviços prestados às famílias | B39: 0.071296714
A40: Serviços de informação e comunicação | B40: 0.25969679
...

Sheet ADs_Setores e Subsetores
A1: Códigos | B1: Setores e Subsetores | C1: Participação Vol (Base 2022)
A2: AD1 | B2: Serviços prestados às famílias | C2: 0.082351118
A3: AD11 | B3: Serviços de alojamento e alimentação | C3: 0.070351048
A4: AD111 | B4: Alojamento | C4: 0.01518555
A5: AD112 | B5: Alimentação | C5: 0.055165498
A6: AD12 | B6: Outros serviços prestados às famílias | C6: 0.01200007
A7: AD2 | B7: Serviços de informação e comunicação | C7: 0.23458168
A8: AD21 | B8: Serviços de Tecnologia de Informação e Comunicação (TIC) | C8: 0.20688493
A9: AD211 | B9: Telecomunicações | C9: 0.10780622
A10: AD212 | B10: Serviços de Tecnologia da Informação | C10: 0.09907871
A11: AD22 | B11: Serviços audiovisuais, de edição e agências de notícias | C11: 0.027696748
A12: AD3 | B12: Serviços profissionais, administrativos e complementares | C12: 0.21670549
A13: AD31 | B13: Serviços técnico-profissionais | C13: 0.083766068
... A29: AD54 | B29: Outros serviços não especificados anteriormente | C29: 0.0075457406
B30: BRASIL | C30: =SUM(C2,C7,C12,C17,C25) -> 1

Sheet Segmentos
A1: Setores | B1: Segmentos de serviços | C1: Participação Vol (Base 2022)
A2: Famílias | B2: 1) Alojamento | C2: ='ADs_Setores e Subsetores'!C4 -> 0.01518555
B3: 2) Alimentação | C3: ='ADs_Setores e Subsetores'!C5 -> 0.055165498
B4: 3) Outros serviços prestados às famílias | C4: ='ADs_Setores e Subsetores'!C6 -> 0.01200007
A5: Informação e comunicação | B5: 4) Telecomunicações | C5: ='ADs_Setores e Subsetores'!C9 -> 0.10780622
B6: 5) Serviços de tecnologia da informação | C6: ='ADs_Setores e Subsetores'!C10 -> 0.09907871
B7: 6) Serviços audiovisuais | C7: ='ADs_Setores e Subsetores'!C11 -> 0.027696748
A8: Profissionais e administrativos | B8: 7) Serviços técnico-profissionais | C8: ='ADs_Setores e Subsetores'!C13 -> 0.083766068
B9: 8) Aluguéis não imobiliários | C9: ='ADs_Setores e Subsetores'!C15 -> 0.028874253
B10: 9) Serviços de apoio às atividades empresariais | C10: ='ADs_Setores e Subsetores'!C16 -> 0.10406517
A11: Transportes | B11: 10) Rodoviário de cargas | C11: ='ADs_Setores e Subsetores'!C19 -> 0.12748434
B12: 11) Rodoviário de passageiros | C12: ='ADs_Setores e Subsetores'!C20 -> 0.048253869
B13: 12) Outros segmentos do transporte terrestre | C13: ='ADs_Setores e Subsetores'!C21 -> 0.03225603
B14: 13) Transporte Aquaviário | C14: ='ADs_Setores e Subsetores'!C22 -> 0.018732758
B15: 14) Transporte Aéreo | C15: ='ADs_Setores e Subsetores'!C23 -> 0.031784922
B16: 15) Armazenagem, serv. aux. aos transportes e correio | C16: ='ADs_Setores e Subsetores'!C24 -> 0.10551146
A17: Outros serviços | B17: 16) Esgoto, gestão de resíduos, recuperação de materiais e descontaminação | C17: ='ADs_Setores e Subsetores'!C26 -> 0.01401539
B18: 17) Atividades auxiliares dos serviços financeiros | C18: ='ADs_Setores e Subsetores'!C27 -> 0.07208251
B19: 18) Atividades imobiliárias | C19: ='ADs_Setores e Subsetores'!C28 -> 0.0086946925
B20: 19) Outros serviços não especificados anteriormente | C20: ='ADs_Setores e Subsetores'!C29 -> 0.0075457406
B21: BRASIL | C21: =SUM(C2:C20) -> 1

Sheet Turismo_UFs
A1: Unidade da Federação | B1: Pesos_volume (Base 2022)
A2: BRASIL | B2: 1
A3: AMAZONAS | B3: 0.0155
A4: PARÁ | B4: 0.015
A5: CEARÁ | B5: 0.023209783
A6: RIO GRANDE DO NORTE | B6: 0.0099
A7: PERNAMBUCO | B7: 0.034223667
A8: ALAGOAS | B8: 0.0121
A9: BAHIA | B9: 0.048150594
A10: MINAS GERAIS | B10: 0.081210371
A11: ESPÍRITO SANTO | B11: 0.016131601
A12: RIO DE JANEIRO | B12: 0.12427084
A13: SÃO PAULO | B13: 0.38955161
... A20: RESTO DAS UFS | B20: 0.0407
